<mujoco model="g1_23dof">
  <default>
    <default class="robot">
      <default class="motor">
        <joint />
        <motor />
      </default>
      <default class="visual">
        <geom material="visualgeom" contype="0" conaffinity="0" group="2" />
      </default>
      <default class="collision">
        <geom material="collision_material" condim="3" contype="0" conaffinity="1" group="1" solref="0.005 1" friction="1 0.01 0.01" />
        <equality solimp="0.99 0.999 1e-05" solref="0.005 1" />
      </default>
    </default>
  </default>

  <compiler angle="radian" />

  <asset>
    <material name="dark" rgba="0.2 0.2 0.2 1" />
    <material name="white" rgba="0.7 0.7 0.7 1" />
    <material name="collision_material" rgba="1.0 0.28 0.1 0.9" />
    <mesh name="pelvis.STL" file="../meshes/pelvis.STL" />
    <mesh name="pelvis_contour_link.STL" file="../meshes/pelvis_contour_link.STL" />
    <mesh name="left_hip_pitch_link.STL" file="../meshes/left_hip_pitch_link.STL" />
    <mesh name="left_hip_roll_link.STL" file="../meshes/left_hip_roll_link.STL" />
    <mesh name="left_hip_yaw_link.STL" file="../meshes/left_hip_yaw_link.STL" />
    <mesh name="left_knee_link.STL" file="../meshes/left_knee_link.STL" />
    <mesh name="left_ankle_pitch_link.STL" file="../meshes/left_ankle_pitch_link.STL" />
    <mesh name="left_ankle_roll_link.STL" file="../meshes/left_ankle_roll_link.STL" />
    <mesh name="right_hip_pitch_link.STL" file="../meshes/right_hip_pitch_link.STL" />
    <mesh name="right_hip_roll_link.STL" file="../meshes/right_hip_roll_link.STL" />
    <mesh name="right_hip_yaw_link.STL" file="../meshes/right_hip_yaw_link.STL" />
    <mesh name="right_knee_link.STL" file="../meshes/right_knee_link.STL" />
    <mesh name="right_ankle_pitch_link.STL" file="../meshes/right_ankle_pitch_link.STL" />
    <mesh name="right_ankle_roll_link.STL" file="../meshes/right_ankle_roll_link.STL" />
    <mesh name="torso_link.STL" file="../meshes/torso_link.STL" />
    <mesh name="waist_yaw_link.STL" file="../meshes/waist_yaw_link.STL" />
    <mesh name="head_link.STL" file="../meshes/head_link.STL" />
    <mesh name="waist_support_link.STL" file="../meshes/waist_support_link.STL" />
    <mesh name="left_shoulder_pitch_link.STL" file="../meshes/left_shoulder_pitch_link.STL" />
    <mesh name="left_shoulder_roll_link.STL" file="../meshes/left_shoulder_roll_link.STL" />
    <mesh name="left_shoulder_yaw_link.STL" file="../meshes/left_shoulder_yaw_link.STL" />
    <mesh name="left_elbow_link.STL" file="../meshes/left_elbow_link.STL" />
    <mesh name="left_wrist_roll_rubber_hand.STL" file="../meshes/left_wrist_roll_rubber_hand.STL" />
    <mesh name="right_shoulder_pitch_link.STL" file="../meshes/right_shoulder_pitch_link.STL" />
    <mesh name="right_shoulder_roll_link.STL" file="../meshes/right_shoulder_roll_link.STL" />
    <mesh name="right_shoulder_yaw_link.STL" file="../meshes/right_shoulder_yaw_link.STL" />
    <mesh name="right_elbow_link.STL" file="../meshes/right_elbow_link.STL" />
    <mesh name="right_wrist_roll_rubber_hand.STL" file="../meshes/right_wrist_roll_rubber_hand.STL" />
  </asset>

  <worldbody>
    <body name="pelvis" pos="0.00000000 0.00000000 0.79186375" quat="1 0 0 0" childclass="robot">
      <freejoint name="floating_base" />
      <geom name="pelvis_visual" pos="0 0 0" quat="1.0 0.0 0.0 0.0" material="dark" type="mesh" mesh="pelvis.STL" class="visual" />
      <body name="pelvis_contour_link" pos="0 0 0" quat="1 0 0 0">
        <inertial pos="0 0 0" quat="1.0 0.0 0.0 0.0" mass="0.001" diaginertia="1e-07 1e-07 1e-07" />
        <geom name="pelvis_contour_link_collision" pos="0 0 0" quat="1.0 0.0 0.0 0.0" type="mesh" mesh="pelvis_contour_link.STL" class="collision" />
        <geom name="pelvis_contour_link_visual" pos="0 0 0" quat="1.0 0.0 0.0 0.0" material="white" type="mesh" mesh="pelvis_contour_link.STL" class="visual" />
      </body>
      <body name="left_hip_pitch_link" pos="0 0.064452 -0.1027" quat="1.0 0.0 0.0 0.0">
        <joint name="left_hip_pitch_joint" type="hinge" ref="0.0" class="motor" range="-2.5307 2.8798" axis="0 1 0" />
        <inertial pos="0.002741 0.047791 -0.02606" quat="1.0 0.0 0.0 0.0" mass="1.35" diaginertia="0.001811 0.0014193 0.0012812" />
        <geom name="left_hip_pitch_link_collision" pos="0 0 0" quat="1.0 0.0 0.0 0.0" type="mesh" mesh="left_hip_pitch_link.STL" class="collision" />
        <geom name="left_hip_pitch_link_visual" pos="0 0 0" quat="1.0 0.0 0.0 0.0" material="dark" type="mesh" mesh="left_hip_pitch_link.STL" class="visual" />
        <body name="left_hip_roll_link" pos="0 0.052 -0.030465" quat="0.9961786849744957 0.0 -0.08733858026373247 0.0">
          <joint name="left_hip_roll_joint" type="hinge" ref="0.0" class="motor" range="-0.5236 2.9671" axis="1 0 0" />
          <inertial pos="0.029812 -0.001045 -0.087934" quat="1.0 0.0 0.0 0.0" mass="1.52" diaginertia="0.0023773 0.0024123 0.0016595" />
          <geom name="left_hip_roll_link_collision" pos="0 0 0" quat="1.0 0.0 0.0 0.0" type="mesh" mesh="left_hip_roll_link.STL" class="collision" />
          <geom name="left_hip_roll_link_visual" pos="0 0 0" quat="1.0 0.0 0.0 0.0" material="white" type="mesh" mesh="left_hip_roll_link.STL" class="visual" />
          <body name="left_hip_yaw_link" pos="0.025001 0 -0.12412" quat="1.0 0.0 0.0 0.0">
            <joint name="left_hip_yaw_joint" type="hinge" ref="0.0" class="motor" range="-2.7576 2.7576" axis="0 0 1" />
            <inertial pos="-0.057709 -0.010981 -0.15078" quat="1.0 0.0 0.0 0.0" mass="1.702" diaginertia="0.0057774 0.0076124 0.003149" />
            <geom name="left_hip_yaw_link_collision" pos="0 0 0" quat="1.0 0.0 0.0 0.0" type="mesh" mesh="left_hip_yaw_link.STL" class="collision" />
            <geom name="left_hip_yaw_link_visual" pos="0 0 0" quat="1.0 0.0 0.0 0.0" material="white" type="mesh" mesh="left_hip_yaw_link.STL" class="visual" />
            <body name="left_knee_link" pos="-0.078273 0.0021489 -0.17734" quat="0.9961786849744957 0.0 0.08733858026373247 0.0">
              <joint name="left_knee_joint" type="hinge" ref="0.0" class="motor" range="-0.087267 2.8798" axis="0 1 0" />
              <inertial pos="0.005457 0.003964 -0.12074" quat="1.0 0.0 0.0 0.0" mass="1.932" diaginertia="0.011329 0.011277 0.0015168" />
              <geom name="left_knee_link_collision" pos="0 0 0" quat="1.0 0.0 0.0 0.0" type="mesh" mesh="left_knee_link.STL" class="collision" />
              <geom name="left_knee_link_visual" pos="0 0 0" quat="1.0 0.0 0.0 0.0" material="white" type="mesh" mesh="left_knee_link.STL" class="visual" />
              <body name="left_ankle_pitch_link" pos="0 -9.4445E-05 -0.30001" quat="1.0 0.0 0.0 0.0">
                <joint name="left_ankle_pitch_joint" type="hinge" ref="0.0" class="motor" range="-0.87267 0.5236" axis="0 1 0" />
                <inertial pos="-0.007269 0 0.011137" quat="1.0 0.0 0.0 0.0" mass="0.074" diaginertia="8.4e-06 1.89e-05 1.26e-05" />
                <geom name="left_ankle_pitch_link_collision" pos="0 0 0" quat="1.0 0.0 0.0 0.0" type="mesh" mesh="left_ankle_pitch_link.STL" class="collision" />
                <geom name="left_ankle_pitch_link_visual" pos="0 0 0" quat="1.0 0.0 0.0 0.0" material="white" type="mesh" mesh="left_ankle_pitch_link.STL" class="visual" />
                <body name="left_ankle_roll_link" pos="0 0 -0.017558" quat="1.0 0.0 0.0 0.0">
                  <joint name="left_ankle_roll_joint" type="hinge" ref="0.0" class="motor" range="-0.2618 0.2618" axis="1 0 0" />
                  <inertial pos="0.026505 0 -0.016425" quat="1.0 0.0 0.0 0.0" mass="0.608" diaginertia="0.0002231 0.0016161 0.0016667" />
                  <geom name="left_ankle_roll_link_collision_0" pos="-0.05 0.025 -0.03" quat="1.0 0.0 0.0 0.0" type="sphere" size="0.005" class="collision" />
                  <geom name="left_ankle_roll_link_collision_1" pos="-0.05 -0.025 -0.03" quat="1.0 0.0 0.0 0.0" type="sphere" size="0.005" class="collision" />
                  <geom name="left_ankle_roll_link_collision_2" pos="0.12 0.03 -0.03" quat="1.0 0.0 0.0 0.0" type="sphere" size="0.005" class="collision" />
                  <geom name="left_ankle_roll_link_collision_3" pos="0.12 -0.03 -0.03" quat="1.0 0.0 0.0 0.0" type="sphere" size="0.005" class="collision" />
                  <geom name="left_ankle_roll_link_visual" pos="0 0 0" quat="1.0 0.0 0.0 0.0" material="dark" type="mesh" mesh="left_ankle_roll_link.STL" class="visual" />
                </body>
              </body>
            </body>
          </body>
        </body>
      </body>
      <body name="right_hip_pitch_link" pos="0 -0.064452 -0.1027" quat="1.0 0.0 0.0 0.0">
        <joint name="right_hip_pitch_joint" type="hinge" ref="0.0" class="motor" range="-2.5307 2.8798" axis="0 1 0" />
        <inertial pos="0.002741 -0.047791 -0.02606" quat="1.0 0.0 0.0 0.0" mass="1.35" diaginertia="0.001811 0.0014193 0.0012812" />
        <geom name="right_hip_pitch_link_collision" pos="0 0 0" quat="1.0 0.0 0.0 0.0" type="mesh" mesh="right_hip_pitch_link.STL" class="collision" />
        <geom name="right_hip_pitch_link_visual" pos="0 0 0" quat="1.0 0.0 0.0 0.0" material="dark" type="mesh" mesh="right_hip_pitch_link.STL" class="visual" />
        <body name="right_hip_roll_link" pos="0 -0.052 -0.030465" quat="0.9961786849744957 0.0 -0.08733858026373247 0.0">
          <joint name="right_hip_roll_joint" type="hinge" ref="0.0" class="motor" range="-2.9671 0.5236" axis="1 0 0" />
          <inertial pos="0.029812 0.001045 -0.087934" quat="1.0 0.0 0.0 0.0" mass="1.52" diaginertia="0.0023773 0.0024123 0.0016595" />
          <geom name="right_hip_roll_link_collision" pos="0 0 0" quat="1.0 0.0 0.0 0.0" type="mesh" mesh="right_hip_roll_link.STL" class="collision" />
          <geom name="right_hip_roll_link_visual" pos="0 0 0" quat="1.0 0.0 0.0 0.0" material="white" type="mesh" mesh="right_hip_roll_link.STL" class="visual" />
          <body name="right_hip_yaw_link" pos="0.025001 0 -0.12412" quat="1.0 0.0 0.0 0.0">
            <joint name="right_hip_yaw_joint" type="hinge" ref="0.0" class="motor" range="-2.7576 2.7576" axis="0 0 1" />
            <inertial pos="-0.057709 0.010981 -0.15078" quat="1.0 0.0 0.0 0.0" mass="1.702" diaginertia="0.0057774 0.0076124 0.003149" />
            <geom name="right_hip_yaw_link_collision" pos="0 0 0" quat="1.0 0.0 0.0 0.0" type="mesh" mesh="right_hip_yaw_link.STL" class="collision" />
            <geom name="right_hip_yaw_link_visual" pos="0 0 0" quat="1.0 0.0 0.0 0.0" material="white" type="mesh" mesh="right_hip_yaw_link.STL" class="visual" />
            <body name="right_knee_link" pos="-0.078273 -0.0021489 -0.17734" quat="0.9961786849744957 0.0 0.08733858026373247 0.0">
              <joint name="right_knee_joint" type="hinge" ref="0.0" class="motor" range="-0.087267 2.8798" axis="0 1 0" />
              <inertial pos="0.005457 -0.003964 -0.12074" quat="1.0 0.0 0.0 0.0" mass="1.932" diaginertia="0.011329 0.011277 0.0015168" />
              <geom name="right_knee_link_collision" pos="0 0 0" quat="1.0 0.0 0.0 0.0" type="mesh" mesh="right_knee_link.STL" class="collision" />
              <geom name="right_knee_link_visual" pos="0 0 0" quat="1.0 0.0 0.0 0.0" material="white" type="mesh" mesh="right_knee_link.STL" class="visual" />
              <body name="right_ankle_pitch_link" pos="0 9.4445E-05 -0.30001" quat="1.0 0.0 0.0 0.0">
                <joint name="right_ankle_pitch_joint" type="hinge" ref="0.0" class="motor" range="-0.87267 0.5236" axis="0 1 0" />
                <inertial pos="-0.007269 0 0.011137" quat="1.0 0.0 0.0 0.0" mass="0.074" diaginertia="8.4e-06 1.89e-05 1.26e-05" />
                <geom name="right_ankle_pitch_link_collision" pos="0 0 0" quat="1.0 0.0 0.0 0.0" type="mesh" mesh="right_ankle_pitch_link.STL" class="collision" />
                <geom name="right_ankle_pitch_link_visual" pos="0 0 0" quat="1.0 0.0 0.0 0.0" material="white" type="mesh" mesh="right_ankle_pitch_link.STL" class="visual" />
                <body name="right_ankle_roll_link" pos="0 0 -0.017558" quat="1.0 0.0 0.0 0.0">
                  <joint name="right_ankle_roll_joint" type="hinge" ref="0.0" class="motor" range="-0.2618 0.2618" axis="1 0 0" />
                  <inertial pos="0.026505 0 -0.016425" quat="1.0 0.0 0.0 0.0" mass="0.608" diaginertia="0.0002231 0.0016161 0.0016667" />
                  <geom name="right_ankle_roll_link_collision_0" pos="-0.05 0.025 -0.03" quat="1.0 0.0 0.0 0.0" type="sphere" size="0.005" class="collision" />
                  <geom name="right_ankle_roll_link_collision_1" pos="-0.05 -0.025 -0.03" quat="1.0 0.0 0.0 0.0" type="sphere" size="0.005" class="collision" />
                  <geom name="right_ankle_roll_link_collision_2" pos="0.12 0.03 -0.03" quat="1.0 0.0 0.0 0.0" type="sphere" size="0.005" class="collision" />
                  <geom name="right_ankle_roll_link_collision_3" pos="0.12 -0.03 -0.03" quat="1.0 0.0 0.0 0.0" type="sphere" size="0.005" class="collision" />
                  <geom name="right_ankle_roll_link_visual" pos="0 0 0" quat="1.0 0.0 0.0 0.0" material="dark" type="mesh" mesh="right_ankle_roll_link.STL" class="visual" />
                </body>
              </body>
            </body>
          </body>
        </body>
      </body>
      <body name="torso_link" pos="-0.0039635 0 0.054" quat="1.0 0.0 0.0 0.0">
        <inertial pos="0.002601 0.000257 0.153719" quat="1.0 0.0 0.0 0.0" mass="8.562" diaginertia="0.065674966 0.053535188 0.030808125" />
        <geom name="torso_link_collision" pos="0 0 0" quat="1.0 0.0 0.0 0.0" type="mesh" mesh="torso_link.STL" class="collision" />
        <geom name="torso_link_visual" pos="0 0 0" quat="1.0 0.0 0.0 0.0" material="white" type="mesh" mesh="torso_link.STL" class="visual" />
        <body name="waist_yaw_fixed_link" pos="0.0039635 0 -0.054" quat="1.0 0.0 0.0 0.0">
          <inertial pos="0.003964 0 0.018769" quat="1.0 0.0 0.0 0.0" mass="0.244" diaginertia="9.9587e-05 0.00012411 0.00015586" />
          <geom name="waist_yaw_fixed_link_visual" pos="0 0 0" quat="1.0 0.0 0.0 0.0" material="white" type="mesh" mesh="waist_yaw_link.STL" class="visual" />
        </body>
        <body name="head_link" pos="0.0039635 0 -0.054" quat="1.0 0.0 0.0 0.0">
          <inertial pos="0.005267 0.000299 0.449869" quat="1.0 0.0 0.0 0.0" mass="1.036" diaginertia="0.004085051 0.004185212 0.001807911" />
          <geom name="head_link_collision" pos="0 0 0" quat="1.0 0.0 0.0 0.0" type="mesh" mesh="head_link.STL" class="collision" />
          <geom name="head_link_visual" pos="0 0 0" quat="1.0 0.0 0.0 0.0" material="dark" type="mesh" mesh="head_link.STL" class="visual" />
        </body>
        <body name="waist_support_link" pos="0.0039635 0 -0.054" quat="1.0 0.0 0.0 0.0">
          <inertial pos="0 0 0" quat="1.0 0.0 0.0 0.0" mass="0.001" diaginertia="1e-07 1e-07 1e-07" />
          <geom name="waist_support_link_collision" pos="0 0 0" quat="1.0 0.0 0.0 0.0" type="mesh" mesh="waist_support_link.STL" class="collision" />
          <geom name="waist_support_link_visual" pos="0 0 0" quat="1.0 0.0 0.0 0.0" material="white" type="mesh" mesh="waist_support_link.STL" class="visual" />
        </body>
        <body name="imu_in_torso" pos="-0.03959 -0.00224 0.13792" quat="1.0 0.0 0.0 0.0" />
        <body name="d435_link" pos="0.0576235 0.01753 0.41987" quat="0.9149596678498247 0.0 0.40354529635239006 0.0" />
        <body name="mid360_link" pos="0.0002835 0.00003 0.40618" quat="0.9997985784932998 0.0 0.020069938783589012 0.0" />
        <body name="left_shoulder_pitch_link" pos="0.0039563 0.10022 0.23778" quat="0.9902640743722195 0.13920148374281427 1.3872204401988457e-05 -9.868683842420437e-05">
          <inertial pos="0 0.035892 -0.011628" quat="1.0 0.0 0.0 0.0" mass="0.718" diaginertia="0.0004291 0.000453 0.000423" />
          <geom name="left_shoulder_pitch_link_collision" pos="0 0.04 -0.01" quat="0.7071067811865476 0.0 0.7071067811865475 0.0" type="cylinder" size="0.03 0.025" class="collision" />
          <geom name="left_shoulder_pitch_link_visual" pos="0 0 0" quat="1.0 0.0 0.0 0.0" material="white" type="mesh" mesh="left_shoulder_pitch_link.STL" class="visual" />
          <body name="left_shoulder_roll_link" pos="0 0.038 -0.013831" quat="0.9902682552548409 -0.1391717738427347 0.0 0.0">
            <inertial pos="-0.000227 0.00727 -0.063243" quat="1.0 0.0 0.0 0.0" mass="0.643" diaginertia="0.0006177 0.0006912 0.0003894" />
            <geom name="left_shoulder_roll_link_collision" pos="-0.004 0.006 -0.053" quat="1.0 0.0 0.0 0.0" type="cylinder" size="0.03 0.015" class="collision" />
            <geom name="left_shoulder_roll_link_visual" pos="0 0 0" quat="1.0 0.0 0.0 0.0" material="white" type="mesh" mesh="left_shoulder_roll_link.STL" class="visual" />
            <body name="left_shoulder_yaw_link" pos="0 0.00624 -0.1032" quat="1.0 0.0 0.0 0.0">
              <inertial pos="0.010773 -0.002949 -0.072009" quat="1.0 0.0 0.0 0.0" mass="0.734" diaginertia="0.0009988 0.0010605 0.0004354" />
              <geom name="left_shoulder_yaw_link_collision" pos="0 0 0" quat="1.0 0.0 0.0 0.0" type="mesh" mesh="left_shoulder_yaw_link.STL" class="collision" />
              <geom name="left_shoulder_yaw_link_visual" pos="0 0 0" quat="1.0 0.0 0.0 0.0" material="white" type="mesh" mesh="left_shoulder_yaw_link.STL" class="visual" />
              <body name="left_elbow_link" pos="0.015783 0 -0.080518" quat="1.0 0.0 0.0 0.0">
                <inertial pos="0.064956 0.004454 -0.010062" quat="1.0 0.0 0.0 0.0" mass="0.6" diaginertia="0.0002891 0.0004152 0.0004197" />
                <geom name="left_elbow_link_collision" pos="0 0 0" quat="1.0 0.0 0.0 0.0" type="mesh" mesh="left_elbow_link.STL" class="collision" />
                <geom name="left_elbow_link_visual" pos="0 0 0" quat="1.0 0.0 0.0 0.0" material="white" type="mesh" mesh="left_elbow_link.STL" class="visual" />
                <body name="left_wrist_roll_rubber_hand" pos="0.100 0.00188791 -0.010" quat="1.0 0.0 0.0 0.0">
                  <inertial pos="0.10794656650 0.00163511945 0.00202244863" quat="1.0 0.0 0.0 0.0" mass="0.35692864" diaginertia="0.00019613494735 0.00200280358206 0.00194181412808" />
                  <geom name="left_wrist_roll_rubber_hand_collision" pos="0 0 0" quat="1.0 0.0 0.0 0.0" type="mesh" mesh="left_wrist_roll_rubber_hand.STL" class="collision" />
                  <geom name="left_wrist_roll_rubber_hand_visual" pos="0 0 0" quat="1.0 0.0 0.0 0.0" material="white" type="mesh" mesh="left_wrist_roll_rubber_hand.STL" class="visual" />
                </body>
              </body>
            </body>
          </body>
        </body>
        <body name="right_shoulder_pitch_link" pos="0.0039563 -0.10021 0.23778" quat="0.9902640743722195 -0.13920148374281427 1.3872204401988457e-05 9.868683842420437e-05">
          <inertial pos="0 -0.035892 -0.011628" quat="1.0 0.0 0.0 0.0" mass="0.718" diaginertia="0.0004291 0.000453 0.000423" />
          <geom name="right_shoulder_pitch_link_collision" pos="0 -0.04 -0.01" quat="0.7071067811865476 0.0 0.7071067811865475 0.0" type="cylinder" size="0.03 0.025" class="collision" />
          <geom name="right_shoulder_pitch_link_visual" pos="0 0 0" quat="1.0 0.0 0.0 0.0" material="white" type="mesh" mesh="right_shoulder_pitch_link.STL" class="visual" />
          <body name="right_shoulder_roll_link" pos="0 -0.038 -0.013831" quat="0.9902682552548409 0.1391717738427347 0.0 0.0">
            <inertial pos="-0.000227 -0.00727 -0.063243" quat="1.0 0.0 0.0 0.0" mass="0.643" diaginertia="0.0006177 0.0006912 0.0003894" />
            <geom name="right_shoulder_roll_link_collision" pos="-0.004 -0.006 -0.053" quat="1.0 0.0 0.0 0.0" type="cylinder" size="0.03 0.015" class="collision" />
            <geom name="right_shoulder_roll_link_visual" pos="0 0 0" quat="1.0 0.0 0.0 0.0" material="white" type="mesh" mesh="right_shoulder_roll_link.STL" class="visual" />
            <body name="right_shoulder_yaw_link" pos="0 -0.00624 -0.1032" quat="1.0 0.0 0.0 0.0">
              <inertial pos="0.010773 0.002949 -0.072009" quat="1.0 0.0 0.0 0.0" mass="0.734" diaginertia="0.0009988 0.0010605 0.0004354" />
              <geom name="right_shoulder_yaw_link_collision" pos="0 0 0" quat="1.0 0.0 0.0 0.0" type="mesh" mesh="right_shoulder_yaw_link.STL" class="collision" />
              <geom name="right_shoulder_yaw_link_visual" pos="0 0 0" quat="1.0 0.0 0.0 0.0" material="white" type="mesh" mesh="right_shoulder_yaw_link.STL" class="visual" />
              <body name="right_elbow_link" pos="0.015783 0 -0.080518" quat="1.0 0.0 0.0 0.0">
                <inertial pos="0.064956 -0.004454 -0.010062" quat="1.0 0.0 0.0 0.0" mass="0.6" diaginertia="0.0002891 0.0004152 0.0004197" />
                <geom name="right_elbow_link_collision" pos="0 0 0" quat="1.0 0.0 0.0 0.0" type="mesh" mesh="right_elbow_link.STL" class="collision" />
                <geom name="right_elbow_link_visual" pos="0 0 0" quat="1.0 0.0 0.0 0.0" material="white" type="mesh" mesh="right_elbow_link.STL" class="visual" />
                <body name="right_wrist_roll_rubber_hand" pos="0.100 -0.00188791 -0.010" quat="1.0 0.0 0.0 0.0">
                  <inertial pos="0.10794656650 -0.00163511945 0.00202244863" quat="1.0 0.0 0.0 0.0" mass="0.35692864" diaginertia="0.00019613494735 0.00200280358206 0.00194181412808" />
                  <geom name="right_wrist_roll_rubber_hand_collision" pos="0 0 0" quat="1.0 0.0 0.0 0.0" type="mesh" mesh="right_wrist_roll_rubber_hand.STL" class="collision" />
                  <geom name="right_wrist_roll_rubber_hand_visual" pos="0 0 0" quat="1.0 0.0 0.0 0.0" material="white" type="mesh" mesh="right_wrist_roll_rubber_hand.STL" class="visual" />
                </body>
              </body>
            </body>
          </body>
        </body>
      </body>
      <body name="imu_in_pelvis" pos="0.04525 0 -0.08339" quat="1.0 0.0 0.0 0.0" />
      <site name="pelvis_site" pos="0 0 0" quat="1 0 0 0" />
      <camera name="front_camera" mode="track" fovy="90.0" quat="4.329780281177467e-17 4.329780281177466e-17 0.7071067811865475 0.7071067811865476" pos="0.0 2.0 0.5" />
      <camera name="side_camera" mode="track" fovy="90.0" quat="-0.5 -0.4999999999999999 0.5 0.5000000000000001" pos="-2.0 0.0 0.5" />
    </body>
  </worldbody>

  <actuator>
    <motor name="left_hip_pitch_joint_ctrl" joint="left_hip_pitch_joint" class="motor" />
    <motor name="left_hip_roll_joint_ctrl" joint="left_hip_roll_joint" class="motor" />
    <motor name="left_hip_yaw_joint_ctrl" joint="left_hip_yaw_joint" class="motor" />
    <motor name="left_knee_joint_ctrl" joint="left_knee_joint" class="motor" />
    <motor name="left_ankle_pitch_joint_ctrl" joint="left_ankle_pitch_joint" class="motor" />
    <motor name="left_ankle_roll_joint_ctrl" joint="left_ankle_roll_joint" class="motor" />
    <motor name="right_hip_pitch_joint_ctrl" joint="right_hip_pitch_joint" class="motor" />
    <motor name="right_hip_roll_joint_ctrl" joint="right_hip_roll_joint" class="motor" />
    <motor name="right_hip_yaw_joint_ctrl" joint="right_hip_yaw_joint" class="motor" />
    <motor name="right_knee_joint_ctrl" joint="right_knee_joint" class="motor" />
    <motor name="right_ankle_pitch_joint_ctrl" joint="right_ankle_pitch_joint" class="motor" />
    <motor name="right_ankle_roll_joint_ctrl" joint="right_ankle_roll_joint" class="motor" />
  </actuator>

  <contact>
    <exclude body1="left_hip_pitch_link" body2="left_hip_roll_link" />
    <exclude body1="left_hip_roll_link" body2="left_hip_yaw_link" />
    <exclude body1="left_hip_yaw_link" body2="left_knee_link" />
    <exclude body1="left_knee_link" body2="left_ankle_pitch_link" />
    <exclude body1="left_ankle_pitch_link" body2="left_ankle_roll_link" />
    <exclude body1="right_hip_pitch_link" body2="right_hip_roll_link" />
    <exclude body1="right_hip_roll_link" body2="right_hip_yaw_link" />
    <exclude body1="right_hip_yaw_link" body2="right_knee_link" />
    <exclude body1="right_knee_link" body2="right_ankle_pitch_link" />
    <exclude body1="right_ankle_pitch_link" body2="right_ankle_roll_link" />
    <exclude body1="torso_link" body2="head_link" />
    <exclude body1="torso_link" body2="waist_support_link" />
    <exclude body1="torso_link" body2="left_shoulder_pitch_link" />
    <exclude body1="left_shoulder_pitch_link" body2="left_shoulder_roll_link" />
    <exclude body1="left_shoulder_roll_link" body2="left_shoulder_yaw_link" />
    <exclude body1="left_shoulder_yaw_link" body2="left_elbow_link" />
    <exclude body1="left_elbow_link" body2="left_wrist_roll_rubber_hand" />
    <exclude body1="torso_link" body2="right_shoulder_pitch_link" />
    <exclude body1="right_shoulder_pitch_link" body2="right_shoulder_roll_link" />
    <exclude body1="right_shoulder_roll_link" body2="right_shoulder_yaw_link" />
    <exclude body1="right_shoulder_yaw_link" body2="right_elbow_link" />
    <exclude body1="right_elbow_link" body2="right_wrist_roll_rubber_hand" />
  </contact>

  <sensor>
    <framepos name="pelvis_site_pos" objtype="site" objname="pelvis_site" />
    <framequat name="pelvis_site_quat" objtype="site" objname="pelvis_site" />
    <framelinvel name="pelvis_site_linvel" objtype="site" objname="pelvis_site" />
    <frameangvel name="pelvis_site_angvel" objtype="site" objname="pelvis_site" />
    <velocimeter name="pelvis_site_vel" site="pelvis_site" />
  </sensor>
</mujoco>